<?xml version="1.0"?>

<robot xmlns:controller="http://playerstage.sourceforge.net/gazebo/xmlschema/#controller"
  xmlns:interface="http://playerstage.sourceforge.net/gazebo/xmlschema/#interface"
  xmlns:sensor="http://playerstage.sourceforge.net/gazebo/xmlschema/#sensor"
  xmlns:xacro="http://ros.org/wiki/xacro" name="UAGV">

  <link name="base_link"/>

  <joint name="scan_joint" type="fixed">
    <parent link="base_link"/>
    <child link="laser_link"/>
    <origin xyz="0.2815 0 0.15" rpy="0 0 0"/>
  </joint>

  <joint name="wheel_left_joint" type="continuous">
    <parent link="base_link"/>
    <child link="wheel_left_link"/>
    <origin xyz="0.0 0.23 0.09" rpy="-1.57 0 0"/>
    <axis xyz="0 0 1"/>
  </joint>

  <link name="wheel_left_link"/>

  <joint name="wheel_right_joint" type="continuous">
    <parent link="base_link"/>
    <child link="wheel_right_link"/>
    <origin xyz="0.0 -0.23 0.09" rpy="-1.57 0 0"/>
    <axis xyz="0 0 1"/>
  </joint>

  <link name="wheel_right_link"/>

  <xacro:include filename="$(find sick_tim)/urdf/sick_tim.urdf.xacro" />

  <!--xacro:sick_tim310 name="base_laser_link" ros_topic="scan" /-->
  <xacro:sick_tim name="laser" ros_topic="scan" length="0.06" width="0.06" height="0.086" mass="0.250" z_offset="0.06296" min_range="0.05" max_range="10.0" mesh="file://$(find sick_tim)/meshes/sick_tim551.stl"/>

</robot>

